Running experiments sequentially...
Task 1 (blocksworld): Failure (7.0 >= 6.0)
Task 2 (blocksworld): Failure (7.0 >= 6.0)
Task 3 (blocksworld): Failure (6.0 >= 6.0)
Task 4 (blocksworld): Failure (15.0 >= 12.0)
Task 5 (blocksworld): Success (6.0 < 8.0)
Task 6 (blocksworld): Failure (13.0 >= 12.0)
Task 7 (blocksworld): Success (7 < 8.0)
Task 8 (blocksworld): Failure (14.0 >= 14.0)
Task 9 (blocksworld): Failure (22.0 >= 14.0)
Task 10 (blocksworld): Failure (18.0 >= 18.0)
Task 11 (blocksworld): Success (18.0 < 22.0)
Task 12 (blocksworld): Success (18.0 < 20.0)
Task 13 (blocksworld): Success (25.0 < 26.0)
Traceback (most recent call last):
  File "/data/ishika/david/multiagent_helper_llmp/helper_script_n_agents.py", line 729, in <module>
    get_updated_init_conditions(path, args, validation_filename=f"./{path}/p{args.task_id}_{i}_validation.txt", pddl_problem_filename=init_problem, pddl_problem_filename_edited=init_problem_out,is_main=main_goal)
  File "/data/ishika/david/multiagent_helper_llmp/helper_script_n_agents.py", line 211, in get_updated_init_conditions
    with open(validation_filename, 'r') as f:
         ^^^^^^^^^^^^^^^^^^^^^^^^^^^^^^
FileNotFoundError: [Errno 2] No such file or directory: './experiments_multiagent_help/run100/blocksworld/p14_1_validation.txt'
(standard_in) 1: syntax error
Task 14 (blocksworld): Failure ( >= 22.0)
Task 15 (blocksworld): Failure (28.0 >= 26.0)
Task 16 (blocksworld): Failure (32.0 >= 28.0)
Task 17 (blocksworld): Success (21.0 < 22.0)
Task 18 (blocksworld): Failure (37.0 >= 30.0)
Task 19 (blocksworld): Failure (26.0 >= 24.0)
Task 20 (blocksworld): Success (29.0 < 30.0)
Task 1 (grippers): Success (3.0 < 5.0)
Task 2 (grippers): Success (7.0 < 9.0)
Task 3 (grippers): Success (3.0 < 6.0)
Task 4 (grippers): Failure (4 >= 4.0)
Task 5 (grippers): Failure (4 >= 4.0)
Traceback (most recent call last):
  File "/data/ishika/david/multiagent_helper_llmp/helper_script_n_agents.py", line 729, in <module>
    get_updated_init_conditions(path, args, validation_filename=f"./{path}/p{args.task_id}_{i}_validation.txt", pddl_problem_filename=init_problem, pddl_problem_filename_edited=init_problem_out,is_main=main_goal)
  File "/data/ishika/david/multiagent_helper_llmp/helper_script_n_agents.py", line 211, in get_updated_init_conditions
    with open(validation_filename, 'r') as f:
         ^^^^^^^^^^^^^^^^^^^^^^^^^^^^^^
FileNotFoundError: [Errno 2] No such file or directory: './experiments_multiagent_help/run100/grippers/p06_1_validation.txt'
(standard_in) 1: syntax error
Task 6 (grippers): Failure ( >= 4.0)
Task 7 (grippers): Success (4.0 < 8.0)
Task 8 (grippers): Success (5.0 < 11.0)
Task 9 (grippers): Success (13.0 < 17.0)
Task 10 (grippers): Success (4.0 < 10.0)
Task 11 (grippers): Failure (3 >= 3.0)
Task 12 (grippers): Success (4.0 < 9.0)
Task 13 (grippers): Success (4.0 < 6.0)
Task 14 (grippers): Success (4.0 < 6.0)
Task 15 (grippers): Success (4.0 < 10.0)
Task 16 (grippers): Success (14.0 < 19.0)
Task 17 (grippers): Success (4.0 < 8.0)
Task 18 (grippers): Success (4.0 < 9.0)
Task 19 (grippers): Success (12.0 < 17.0)
Task 20 (grippers): Success (4.0 < 7.0)
./run_experiments.sh: line 110: i: command not found

Summary:
--------
blocksworld: 7 successful out of 20
grippers: 16 successful out of 20

Total number of successful experiments across all domains: 23 out of 40
Number of agents used: 3
Run number: 100
Execution mode: Sequential